docker: Error response from daemon: OCI runtime create failed: container_linux.go:348: starting container process caused "exec: \"/gdata/liyh/project/p2p/summit/mru_edge/train.sh\": stat /gdata/liyh/project/p2p/summit/mru_edge/train.sh: no such file or directory": unknown.
/usr/lib/python3.6/importlib/_bootstrap.py:219: RuntimeWarning: compiletime version 3.5 of module 'tensorflow.python.framework.fast_tensor_util' does not match runtime version 3.6
  return f(*args, **kwds)
WARNING:tensorflow:From p2p_mru.py:405: TFRecordDataset.__init__ (from tensorflow.contrib.data.python.ops.readers) is deprecated and will be removed in a future version.
Instructions for updating:
Use `tf.data.TFRecordDataset`.
WARNING:tensorflow:From p2p_mru.py:908: get_or_create_global_step (from tensorflow.contrib.framework.python.ops.variables) is deprecated and will be removed in a future version.
Instructions for updating:
Please switch to tf.train.get_or_create_global_step
2018-09-04 12:31:13.647443: I tensorflow/core/platform/cpu_feature_guard.cc:137] Your CPU supports instructions that this TensorFlow binary was not compiled to use: SSE4.1 SSE4.2 AVX AVX2 FMA
2018-09-04 12:31:14.096124: I tensorflow/core/common_runtime/gpu/gpu_device.cc:1030] Found device 0 with properties: 
name: GeForce GTX 1080 Ti major: 6 minor: 1 memoryClockRate(GHz): 1.62
pciBusID: 0000:04:00.0
totalMemory: 10.92GiB freeMemory: 10.76GiB
2018-09-04 12:31:14.096206: I tensorflow/core/common_runtime/gpu/gpu_device.cc:1120] Creating TensorFlow device (/device:GPU:0) -> (device: 0, name: GeForce GTX 1080 Ti, pci bus id: 0000:04:00.0, compute capability: 6.1)
2018-09-04 12:31:25.883115: W tensorflow/core/framework/op_kernel.cc:1192] Failed precondition: /gdata/liyh/data/CelebA/data/train; Is a directory
Traceback (most recent call last):
  File "/usr/local/lib/python3.6/dist-packages/tensorflow/python/client/session.py", line 1323, in _do_call
    return fn(*args)
  File "/usr/local/lib/python3.6/dist-packages/tensorflow/python/client/session.py", line 1302, in _run_fn
    status, run_metadata)
  File "/usr/local/lib/python3.6/dist-packages/tensorflow/python/framework/errors_impl.py", line 473, in __exit__
    c_api.TF_GetCode(self.status.status))
tensorflow.python.framework.errors_impl.FailedPreconditionError: /gdata/liyh/data/CelebA/data/train; Is a directory
	 [[Node: IteratorGetNext = IteratorGetNext[output_shapes=[[?,256,256,3], [?,256,256,3], [?,?]], output_types=[DT_FLOAT, DT_FLOAT, DT_UINT8], _device="/job:localhost/replica:0/task:0/device:CPU:0"](OneShotIterator)]]

During handling of the above exception, another exception occurred:

Traceback (most recent call last):
  File "p2p_mru.py", line 1266, in <module>
    main()
  File "p2p_mru.py", line 1232, in main
    results = sess.run(fetches, options=options, run_metadata=run_metadata)
  File "/usr/local/lib/python3.6/dist-packages/tensorflow/python/client/session.py", line 889, in run
    run_metadata_ptr)
  File "/usr/local/lib/python3.6/dist-packages/tensorflow/python/client/session.py", line 1120, in _run
    feed_dict_tensor, options, run_metadata)
  File "/usr/local/lib/python3.6/dist-packages/tensorflow/python/client/session.py", line 1317, in _do_run
    options, run_metadata)
  File "/usr/local/lib/python3.6/dist-packages/tensorflow/python/client/session.py", line 1336, in _do_call
    raise type(e)(node_def, op, message)
tensorflow.python.framework.errors_impl.FailedPreconditionError: /gdata/liyh/data/CelebA/data/train; Is a directory
	 [[Node: IteratorGetNext = IteratorGetNext[output_shapes=[[?,256,256,3], [?,256,256,3], [?,?]], output_types=[DT_FLOAT, DT_FLOAT, DT_UINT8], _device="/job:localhost/replica:0/task:0/device:CPU:0"](OneShotIterator)]]

Caused by op 'IteratorGetNext', defined at:
  File "p2p_mru.py", line 1266, in <module>
    main()
  File "p2p_mru.py", line 1087, in main
    examples, iterator  = read_tfrecord()
  File "p2p_mru.py", line 411, in read_tfrecord
    photo, mat, filename = iterator.get_next()
  File "/usr/local/lib/python3.6/dist-packages/tensorflow/python/data/ops/iterator_ops.py", line 259, in get_next
    name=name))
  File "/usr/local/lib/python3.6/dist-packages/tensorflow/python/ops/gen_dataset_ops.py", line 706, in iterator_get_next
    output_shapes=output_shapes, name=name)
  File "/usr/local/lib/python3.6/dist-packages/tensorflow/python/framework/op_def_library.py", line 787, in _apply_op_helper
    op_def=op_def)
  File "/usr/local/lib/python3.6/dist-packages/tensorflow/python/framework/ops.py", line 2956, in create_op
    op_def=op_def)
  File "/usr/local/lib/python3.6/dist-packages/tensorflow/python/framework/ops.py", line 1470, in __init__
    self._traceback = self._graph._extract_stack()  # pylint: disable=protected-access

FailedPreconditionError (see above for traceback): /gdata/liyh/data/CelebA/data/train; Is a directory
	 [[Node: IteratorGetNext = IteratorGetNext[output_shapes=[[?,256,256,3], [?,256,256,3], [?,?]], output_types=[DT_FLOAT, DT_FLOAT, DT_UINT8], _device="/job:localhost/replica:0/task:0/device:CPU:0"](OneShotIterator)]]

